<?xml version="1.0"?>
<robot name="Fish_HPURV" xmlns:xacro="http://www.ros.org/wiki/xacro">

  <!-- ✅ Define Material Properties (Merged from materials.xacro) -->
  <material name="Fish_HPURV_silver">
    <color rgba="0.700 0.700 0.700 1.000"/>
  </material>

  <!-- ✅ Define Gazebo Plugin (Merged from Fish_HPURV.gazebo) -->
  <gazebo>
    <plugin name="control" filename="libgazebo_ros_control.so"/>
  </gazebo>

  <!-- ✅ Define Main Robot Body (Merged from Fish_HPURV_macro.urdf.xacro) -->
  <xacro:macro name="Fish_HPURV" params="prefix">
    <!-- Base Link -->
    <link name="${prefix}base_link">
      <inertial>
        <origin xyz="0 0 0" rpy="0 0 0"/>
        <mass value="5.0"/>
        <inertia ixx="0.01" iyy="0.01" izz="0.01" ixy="0" iyz="0" ixz="0"/>
      </inertial>
      <visual>
        <origin xyz="0 0 0" rpy="0 0 0"/>
        <geometry>
          <mesh filename="package://Fish_HPURV_description/meshes/base_link.stl" scale="0.001 0.001 0.001"/>
        </geometry>
        <material name="Fish_HPURV_silver"/>
      </visual>
      <collision>
        <origin xyz="0 0 0" rpy="0 0 0"/>
        <geometry>
          <mesh filename="package://Fish_HPURV_description/meshes/base_link.stl" scale="0.001 0.001 0.001"/>
        </geometry>
      </collision>
    </link>

    <!-- ✅ Define Fins -->
    <link name="${prefix}Pectal_left">
      <visual>
        <geometry>
          <mesh filename="package://Fish_HPURV_description/meshes/Pectal_left.stl" scale="0.001 0.001 0.001"/>
        </geometry>
      </visual>
    </link>

    <link name="${prefix}Pectal_right">
      <visual>
        <geometry>
          <mesh filename="package://Fish_HPURV_description/meshes/Pectal_right.stl" scale="0.001 0.001 0.001"/>
        </geometry>
      </visual>
    </link>

    <link name="${prefix}Caudal_Fin">
      <visual>
        <geometry>
          <mesh filename="package://Fish_HPURV_description/meshes/Caudal_Fin.stl" scale="0.001 0.001 0.001"/>
        </geometry>
      </visual>
    </link>

    <!-- ✅ Define Joints -->
    <joint name="${prefix}Revolute_2" type="revolute">
      <origin xyz="-0.082983 -0.047057 0.139" rpy="0 0 0"/>
      <parent link="${prefix}base_link"/>
      <child link="${prefix}Pectal_left"/>
      <axis xyz="1.0 0.0 0.0"/>
      <limit upper="0.785398" lower="-0.785398" effort="100" velocity="100"/>
    </joint>

    <joint name="${prefix}Revolute_7" type="revolute">
      <origin xyz="-0.082983 -0.047057 -0.14" rpy="0 0 0"/>
      <parent link="${prefix}base_link"/>
      <child link="${prefix}Pectal_right"/>
      <axis xyz="0.0 0.0 -1.0"/>
      <limit upper="0.785398" lower="-0.785398" effort="100" velocity="100"/>
    </joint>

    <joint name="${prefix}Revolute_8" type="revolute">
      <origin xyz="0.392742 -0.028093 0.0" rpy="0 0 0"/>
      <parent link="${prefix}base_link"/>
      <child link="${prefix}Caudal_Fin"/>
      <axis xyz="-0.173648 0.984808 0.0"/>
      <limit upper="0.785398" lower="-0.785398" effort="100" velocity="100"/>
    </joint>

    <!-- ✅ Add Gazebo Properties for Links -->
    <gazebo reference="${prefix}base_link">
      <material>Gazebo/Silver</material>
      <mu1>0.2</mu1>
      <mu2>0.2</mu2>
      <self_collide>true</self_collide>
      <gravity>true</gravity>
    </gazebo>

    <gazebo reference="${prefix}Pectal_left">
      <material>Gazebo/Silver</material>
      <mu1>0.2</mu1>
      <mu2>0.2</mu2>
      <self_collide>true</self_collide>
    </gazebo>

    <gazebo reference="${prefix}Pectal_right">
      <material>Gazebo/Silver</material>
      <mu1>0.2</mu1>
      <mu2>0.2</mu2>
      <self_collide>true</self_collide>
    </gazebo>

    <gazebo reference="${prefix}Caudal_Fin">
      <material>Gazebo/Silver</material>
      <mu1>0.2</mu1>
      <mu2>0.2</mu2>
      <self_collide>true</self_collide>
    </gazebo>

    <!-- ✅ Transmissions for ROS 2 Control (Merged from Fish_HPURV.trans) -->
    <transmission name="${prefix}Revolute_2_tran">
      <type>transmission_interface/SimpleTransmission</type>
      <joint name="${prefix}Revolute_2">
        <hardwareInterface>hardware_interface/EffortJointInterface</hardwareInterface>
      </joint>
      <actuator name="${prefix}Revolute_2_actr">
        <hardwareInterface>hardware_interface/EffortJointInterface</hardwareInterface>
        <mechanicalReduction>1</mechanicalReduction>
      </actuator>
    </transmission>

    <transmission name="${prefix}Revolute_7_tran">
      <type>transmission_interface/SimpleTransmission</type>
      <joint name="${prefix}Revolute_7">
        <hardwareInterface>hardware_interface/EffortJointInterface</hardwareInterface>
      </joint>
      <actuator name="${prefix}Revolute_7_actr">
        <hardwareInterface>hardware_interface/EffortJointInterface</hardwareInterface>
        <mechanicalReduction>1</mechanicalReduction>
      </actuator>
    </transmission>

    <transmission name="${prefix}Revolute_8_tran">
      <type>transmission_interface/SimpleTransmission</type>
      <joint name="${prefix}Revolute_8">
        <hardwareInterface>hardware_interface/EffortJointInterface</hardwareInterface>
      </joint>
      <actuator name="${prefix}Revolute_8_actr">
        <hardwareInterface>hardware_interface/EffortJointInterface</hardwareInterface>
        <mechanicalReduction>1</mechanicalReduction>
      </actuator>
    </transmission>

  </xacro:macro>

  <!-- Instantiate the Robot -->
  <xacro:Fish_HPURV prefix=""/>

</robot>

