<?xml version="1.0" ?>
<!-- Generated using onshape-to-robot -->
<!-- Onshape document_id: 4836a8ecee0138adbd06e5d4 / workspace_id: a33d52e229ba318a84bbb324 -->
<robot name="fish_hpurv">
  
  <!-- Link link_link1 -->
  <link name="link_link1">
    <inertial>
      <origin xyz="0 0 0" rpy="0 0 0"/>
      <mass value="0.2"/>
      <inertia ixx="0.005" ixy="0" ixz="0" iyy="0.005" iyz="0" izz="0.005"/>
    </inertial>
    <visual>
      <origin xyz="0.0228213 0.0461472 0.010826" rpy="0 0 0"/>
      <geometry>
        <mesh filename="package://fish_hpurv/meshes/link_link1.stl">
          <scale>4 4 4</scale>
        </mesh>
      </geometry>
      <material name="link_link1_material">
        <color rgba="0.615686 0.811765 0.929412 1.0"/>
      </material>
    </visual>
    <collision>
      <origin xyz="0.0228213 0.0461472 0.010826" rpy="0 0 0"/>
      <geometry>
        <mesh filename="package://fish_hpurv/meshes/link_link1.stl">
          <scale>4 4 4</scale>
        </mesh>
      </geometry>
    </collision>
  </link>

  <!-- Link link_link2 -->
  <link name="link_link2">
    <inertial>
      <origin xyz="0 0 0" rpy="0 0 0"/>
      <mass value="0.1"/>
      <inertia ixx="0.001" ixy="0" ixz="0" iyy="0.001" iyz="0" izz="0.001"/>
    </inertial>
    <visual>
      <origin xyz="0 0 0" rpy="3.14159 0 0"/>
      <geometry>
        <mesh filename="package://fish_hpurv/meshes/link_link2.stl">
          <scale>4 4 4</scale>
        </mesh>
      </geometry>
      <material name="link_link2_material">
        <color rgba="0.615686 0.811765 0.929412 1.0"/>
      </material>
    </visual>
    <collision>
      <origin xyz="0 0 0" rpy="3.14159 0 0"/>
      <geometry>
        <mesh filename="package://fish_hpurv/meshes/link_link2.stl">
          <scale>4 4 4</scale>
        </mesh>
      </geometry>
    </collision>
  </link>

  <!-- Joint from link_link1 to link_link2 -->
  <joint name="join1" type="prismatic">
    <origin xyz="0.0228213 0.0461472 0.035826" rpy="3.14159 0 0"/>
    <parent link="link_link1"/>
    <child link="link_link2"/>
    <axis xyz="0 0 1"/>
    <limit effort="10" velocity="10" lower="-1" upper="1"/>
  </joint>
  
  <!-- Mark the robot as static so it won't fall -->
  <gazebo>
    <static>true</static>
  </gazebo>

</robot>
